Workbook
Name NativeTimeline_Date: #N/A
Name NativeTimeline_Date1: #N/A
Name Slicer_Date2: #N/A
Name Slicer_Machine_ID: #N/A
Name Slicer_Product_Type: #N/A
Name Slicer_Shift: #N/A

Sheet data
A1: Production ID | B1: Date | C1: Date2 | D1: Product Type | E1: Machine ID | F1: Shift | G1: Units Produced | H1: Defects | I1: Defects (%) | J1: Production Time Hours | K1: Efficiency | L1: Material Cost Per Unit | M1: Labour Cost Per Hour | N1: Energy Consumption kWh | O1: Operator Count | P1: Maintenance Hours | Q1: Down time Hours | R1: Production Volume Cubic Meters | S1: Scrap Rate | T1: Rework Hours | U1: Quality Checks Failed | V1: Average Temperature C | W1: Average Humidity Percent
A2: 0 | B2: 43831 | C2: January | D2: Automotive | E2: 3 | F2: Swing | G2: 142 | H2: 3 | I2: =IFERROR(Table2[[#This Row],[Defects]]/Table2[[#This Row],[Units Produced]],"") -> 0.021126761 | J2: 23.42 | K2: =IFERROR(Table2[[#This Row],[Units Produced]]/Table2[[#This Row],[Production Time Hours]],"") -> 6.0631939 | L2: 38.68 | M2: 15.38 | N2: 413.97 | O2: 1 | P2: 4.86 | Q2: 1.57 | R2: 2.34 | S2: 0.048 | T2: 1.65 | U2: 1 | V2: 22.8 | W2: 47.2
A3: 1 | B3: 43832 | C3: January | D3: Textiles | E3: 8 | F3: Night | G3: 170 | H3: 4 | I3: =IFERROR(Table2[[#This Row],[Defects]]/Table2[[#This Row],[Units Produced]],"") -> 0.023529412 | J3: 7.51 | K3: =IFERROR(Table2[[#This Row],[Units Produced]]/Table2[[#This Row],[Production Time Hours]],"") -> 22.636485 | L3: 21.35 | M3: 25.36 | N3: 181.16 | O3: 2 | P3: 2.51 | Q3: 0.18 | R3: 1.52 | S3: 0.03 | U3: 1 | V3: 23.8 | W3: 37.9
A4: 2 | B4: 43833 | C4: January | D4: Appliances | E4: 11 | F4: Swing | G4: 182 | H4: 4 | I4: =IFERROR(Table2[[#This Row],[Defects]]/Table2[[#This Row],[Units Produced]],"") -> 0.021978022 | J4: 20.58 | K4: =IFERROR(Table2[[#This Row],[Units Produced]]/Table2[[#This Row],[Production Time Hours]],"") -> 8.8435374 | L4: 47.54 | M4: 16.46 | N4: 452.15 | O4: 2 | P4: 0.34 | Q4: 2.88 | R4: 0.57 | S4: 0.026 | T4: 0.26 | U4: 0 | V4: 24.5 | W4: 56.1
A5: 3 | B5: 43834 | C5: January | D5: Appliances | E5: 11 | F5: Day | G5: 133 | I5: =IFERROR(Table2[[#This Row],[Defects]]/Table2[[#This Row],[Units Produced]],"") -> 0 | J5: 21.68 | K5: =IFERROR(Table2[[#This Row],[Units Produced]]/Table2[[#This Row],[Production Time Hours]],"") -> 6.1346863 | L5: 40.21 | M5: 28.7 | N5: 485.78 | O5: 3 | P5: 4.64 | Q5: 2.23 | R5: 1.9 | S5: 0.036 | U5: 2 | V5: 22.3 | W5: 50.8
A6: 4 | B6: 43835 | C6: January | D6: Electronics | E6: 14 | F6: Night | G6: 82 | I6: =IFERROR(Table2[[#This Row],[Defects]]/Table2[[#This Row],[Units Produced]],"") -> 0 | J6: 16.68 | K6: =IFERROR(Table2[[#This Row],[Units Produced]]/Table2[[#This Row],[Production Time Hours]],"") -> 4.9160671 | L6: 38.02 | M6: 17.2 | N6: 315.58 | O6: 1 | P6: 2.29 | Q6: 0.02 | R6: 2.25 | S6: 0.02 | T6: 0.67 | U6: 0 | V6: 23.4 | W6: 53.9
A7: 5 | B7: 43836 | C7: January | D7: Automotive | E7: 1 | F7: Night | G7: 81 | H7: 0 | I7: =IFERROR(Table2[[#This Row],[Defects]]/Table2[[#This Row],[Units Produced]],"") -> 0 | J7: 11.91 | K7: =IFERROR(Table2[[#This Row],[Units Produced]]/Table2[[#This Row],[Production Time Hours]],"") -> 6.8010076 | L7: 10.66 | M7: 23.25 | N7: 440.42 | O7: 2 | R7: 0.89 | S7: 0.047 | U7: 2 | V7: 20.6 | W7: 56.9
A8: 6 | B8: 43837 | C8: January | D8: Furniture | E8: 20 | F8: Swing | G8: 78 | H8: 8 | I8: =IFERROR(Table2[[#This Row],[Defects]]/Table2[[#This Row],[Units Produced]],"") -> 0.1025641 | J8: 22.98 | K8: =IFERROR(Table2[[#This Row],[Units Produced]]/Table2[[#This Row],[Production Time Hours]],"") -> 3.3942559 | L8: 37.66 | M8: 26.62 | N8: 367.89 | O8: 2 | P8: 2.51 | Q8: 2.83 | R8: 0.82 | S8: 0.036 | T8: 0.86 | U8: 2 | V8: 23.1 | W8: 45.9
A9: 7 | B9: 43838 | C9: January | D9: Textiles | E9: 7 | F9: Night | G9: 151 | H9: 5 | I9: =IFERROR(Table2[[#This Row],[Defects]]/Table2[[#This Row],[Units Produced]],"") -> 0.033112583 | J9: 23.16 | K9: =IFERROR(Table2[[#This Row],[Units Produced]]/Table2[[#This Row],[Production Time Hours]],"") -> 6.5198618 | L9: 30.99 | M9: 27.86 | N9: 197.62 | O9: 3 | P9: 2.1 | Q9: 2.39 | R9: 0.56 | S9: 0.039 | T9: 0.35 | U9: 1 | V9: 23.6 | W9: 59.2
A10: 8 | B10: 43839 | C10: January | D10: Electronics | E10: 16 | F10: Night | G10: 72 | H10: 9 | I10: =IFERROR(Table2[[#This Row],[Defects]]/Table2[[#This Row],[Units Produced]],"") -> 0.125 | J10: 15.63 | K10: =IFERROR(Table2[[#This Row],[Units Produced]]/Table2[[#This Row],[Production Time Hours]],"") -> 4.6065259 | L10: 16.92 | M10: 28.3 | N10: 467.34 | O10: 2 | P10: 0.38 | Q10: 0.82 | R10: 2.02 | S10: 0.041 | T10: 0.59 | U10: 0 | V10: 20.4 | W10: 48.3
A11: 9 | B11: 43840 | C11: January | D11: Textiles | E11: 7 | F11: Night | G11: 189 | H11: 7 | I11: =IFERROR(Table2[[#This Row],[Defects]]/Table2[[#This Row],[Units Produced]],"") -> 0.037037037 | J11: 18.15 | K11: =IFERROR(Table2[[#This Row],[Units Produced]]/Table2[[#This Row],[Production Time Hours]],"") -> 10.413223 | L11: 33.47 | M11: 23.33 | N11: 411.71 | O11: 1 | P11: 0.62 | Q11: 2.03 | R11: 2.32 | S11: 0.042 | T11: 0.24 | U11: 0 | V11: 18.7 | W11: 49.4
A12: 10 | B12: 43841 | C12: January | D12: Textiles | E12: 8 | F12: Day | G12: 124 | H12: 2 | I12: =IFERROR(Table2[[#This Row],[Defects]]/Table2[[#This Row],[Units Produced]],"") -> 0.016129032 | J12: 21.26 | K12: =IFERROR(Table2[[#This Row],[Units Produced]]/Table2[[#This Row],[Production Time Hours]],"") -> 5.8325494 | L12: 14.22 | M12: 18.58 | N12: 456.52 | O12: 4 | P12: 0.56 | Q12: 2.3 | R12: 1.48 | S12: 0.04 | T12: 1.36 | U12: 0 | V12: 20 | W12: 31.7
A13: 11 | B13: 43842 | C13: January | D13: Automotive | E13: 1 | F13: Day | G13: 188 | H13: 8 | I13: =IFERROR(Table2[[#This Row],[Defects]]/Table2[[#This Row],[Units Produced]],"") -> 0.042553191 | J13: 3.46 | K13: =IFERROR(Table2[[#This Row],[Units Produced]]/Table2[[#This Row],[Production Time Hours]],"") -> 54.33526 | L13: 29.45 | M13: 18.05 | N13: 245.14 | O13: 1 | P13: 3.2 | Q13: 1.95 | R13: 1.06 | S13: 0.021 | U13: 0 | V13: 23.5 | W13: 34.4
A14: 12 | B14: 43843 | C14: January | D14: Textiles | E14: 5 | F14: Swing | G14: 172 | H14: 8 | I14: =IFERROR(Table2[[#This Row],[Defects]]/Table2[[#This Row],[Units Produced]],"") -> 0.046511628 | J14: 14 | K14: =IFERROR(Table2[[#This Row],[Units Produced]]/Table2[[#This Row],[Production Time Hours]],"") -> 12.285714 | L14: 17.66 | M14: 21.72 | N14: 281.45 | O14: 3 | P14: 2.66 | Q14: 2.69 | R14: 2.35 | S14: 0.036 | T14: 0.89 | U14: 0 | V14: 24.4 | W14: 51.4
A15: 13 | B15: 43844 | C15: January | D15: Textiles | E15: 5 | F15: Day | G15: 70 | H15: 6 | I15: =IFERROR(Table2[[#This Row],[Defects]]/Table2[[#This Row],[Units Produced]],"") -> 0.085714286 | J15: 20.86 | K15: =IFERROR(Table2[[#This Row],[Units Produced]]/Table2[[#This Row],[Production Time Hours]],"") -> 3.3557047 | L15: 10.42 | M15: 24.44 | N15: 215.36 | O15: 1 | P15: 4.93 | Q15: 0.7 | R15: 0.9 | S15: 0.034 | U15: 2 | V15: 20.1 | W15: 47.9
A16: 14 | B16: 43845 | C16: January | D16: Furniture | E16: 17 | F16: Night | G16: 55 | H16: 1 | I16: =IFERROR(Table2[[#This Row],[Defects]]/Table2[[#This Row],[Units Produced]],"") -> 0.018181818 | J16: 22 | K16: =IFERROR(Table2[[#This Row],[Units Produced]]/Table2[[#This Row],[Production Time Hours]],"") -> 2.5 | L16: 24.82 | M16: 27.92 | N16: 234.33 | O16: 4 | P16: 2.17 | R16: 1.35 | S16: 0.047 | T16: 1.31 | U16: 2 | V16: 24.6 | W16: 59.1
A17: 15 | B17: 43846 | C17: January | D17: Automotive | E17: 3 | F17: Night | G17: 136 | H17: 6 | I17: =IFERROR(Table2[[#This Row],[Defects]]/Table2[[#This Row],[Units Produced]],"") -> 0.044117647 | J17: 23.99 | K17: =IFERROR(Table2[[#This Row],[Units Produced]]/Table2[[#This Row],[Production Time Hours]],"") -> 5.6690288 | L17: 24.74 | M17: 22.55 | N17: 204.39 | O17: 4 | P17: 0.8 | R17: 2.31 | S17: 0.04 | U17: 0 | V17: 21.4 | W17: 41.2
A18: 16 | B18: 43847 | C18: January | D18: Furniture | E18: 20 | F18: Swing | G18: 152 | H18: 4 | I18: =IFERROR(Table2[[#This Row],[Defects]]/Table2[[#This Row],[Units Produced]],"") -> 0.026315789 | J18: 17.86 | K18: =IFERROR(Table2[[#This Row],[Units Produced]]/Table2[[#This Row],[Production Time Hours]],"") -> 8.5106383 | L18: 30.65 | M18: 25.52 | N18: 390.9 | O18: 1 | P18: 1.41 | Q18: 2.9 | R18: 2.48 | S18: 0.032 | T18: 0.36 | U18: 2 | V18: 25 | W18: 54.6
A19: 17 | B19: 43848 | C19: January | D19: Electronics | E19: 13 | F19: Swing | G19: 120 | H19: 5 | I19: =IFERROR(Table2[[#This Row],[Defects]]/Table2[[#This Row],[Units Produced]],"") -> 0.041666667 | J19: 5.81 | K19: =IFERROR(Table2[[#This Row],[Units Produced]]/Table2[[#This Row],[Production Time Hours]],"") -> 20.654045 | L19: 48.47 | M19: 25.35 | N19: 251.57 | O19: 1 | P19: 4.01 | Q19: 2.05 | R19: 1.03 | S19: 0.047 | T19: 1.4 | U19: 2 | V19: 22.2 | W19: 52
A20: 18 | B20: 43849 | C20: January | D20: Appliances | E20: 10 | F20: Day | G20: 158 | H20: 8 | I20: =IFERROR(Table2[[#This Row],[Defects]]/Table2[[#This Row],[Units Produced]],"") -> 0.050632911 | J20: 15.59 | K20: =IFERROR(Table2[[#This Row],[Units Produced]]/Table2[[#This Row],[Production Time Hours]],"") -> 10.134702 | L20: 13.18 | M20: 16.77 | N20: 392.66 | O20: 2 | P20: 4.12 | Q20: 1.3 | R20: 2.4 | S20: 0.044 | T20: 0.93 | U20: 2 | V20: 19.1 | W20: 35.6
A21: 19 | B21: 43850 | C21: January | D21: Textiles | E21: 8 | F21: Swing | G21: 85 | H21: 2 | I21: =IFERROR(Table2[[#This Row],[Defects]]/Table2[[#This Row],[Units Produced]],"") -> 0.023529412 | J21: 23.76 | K21: =IFERROR(Table2[[#This Row],[Units Produced]]/Table2[[#This Row],[Production Time Hours]],"") -> 3.5774411 | L21: 18.96 | M21: 27.23 | N21: 369.77 | O21: 4 | P21: 0.59 | Q21: 0.35 | R21: 1.46 | S21: 0.022 | T21: 1.39 | U21: 0 | V21: 23.2 | W21: 35.6
A22: 20 | B22: 43851 | C22: January | D22: Automotive | E22: 4 | F22: Night | G22: 64 | H22: 2 | I22: =IFERROR(Table2[[#This Row],[Defects]]/Table2[[#This Row],[Units Produced]],"") -> 0.03125 | J22: 14.51 | K22: =IFERROR(Table2[[#This Row],[Units Produced]]/Table2[[#This Row],[Production Time Hours]],"") -> 4.4107512 | L22: 28.02 | M22: 21.45 | N22: 322.07 | O22: 1 | P22: 4.93 | Q22: 1.91 | R22: 1.77 | S22: 0.047 | T22: 0.9 | U22: 1 | V22: 20.4 | W22: 35.3
A23: 21 | B23: 43852 | C23: January | D23: Appliances | E23: 10 | F23: Swing | G23: 58 | H23: 2 | I23: =IFERROR(Table2[[#This Row],[Defects]]/Table2[[#This Row],[Units Produced]],"") -> 0.034482759 | J23: 9.87 | K23: =IFERROR(Table2[[#This Row],[Units Produced]]/Table2[[#This Row],[Production Time Hours]],"") -> 5.8763931 | L23: 23.97 | M23: 15.85 | N23: 368.7 | O23: 1 | P23: 1.76 | Q23: 2.87 | R23: 2.02 | S23: 0.029 | T23: 0.33 | U23: 1 | V23: 22.1 | W23: 41.3
A24: 22 | B24: 43853 | C24: January | D24: Textiles | E24: 8 | F24: Day | G24: 96 | H24: 8 | I24: =IFERROR(Table2[[#This Row],[Defects]]/Table2[[#This Row],[Units Produced]],"") -> 0.083333333 | J24: 7.24 | K24: =IFERROR(Table2[[#This Row],[Units Produced]]/Table2[[#This Row],[Production Time Hours]],"") -> 13.259669 | L24: 32.58 | M24: 23.54 | N24: 321.45 | O24: 3 | P24: 1.79 | Q24: 1 | R24: 1.24 | S24: 0.021 | T24: 1.18 | U24: 1 | V24: 19.8 | W24: 34.2
A25: 23 | B25: 43854 | C25: January | D25: Textiles | E25: 6 | F25: Day | G25: 135 | H25: 2 | I25: =IFERROR(Table2[[#This Row],[Defects]]/Table2[[#This Row],[Units Produced]],"") -> 0.014814815 | J25: 9.03 | K25: =IFERROR(Table2[[#This Row],[Units Produced]]/Table2[[#This Row],[Production Time Hours]],"") -> 14.950166 | L25: 42.16 | M25: 28.61 | N25: 387.81 | O25: 3 | P25: 1.42 | Q25: 1.97 | R25: 2.17 | S25: 0.017 | T25: 1.77 | U25: 0 | V25: 23.1 | W25: 56
A26: 24 | B26: 43855 | C26: January | D26: Appliances | E26: 9 | F26: Night | G26: 188 | H26: 5 | I26: =IFERROR(Table2[[#This Row],[Defects]]/Table2[[#This Row],[Units Produced]],"") -> 0.026595745 | J26: 17.93 | K26: =IFERROR(Table2[[#This Row],[Units Produced]]/Table2[[#This Row],[Production Time Hours]],"") -> 10.48522 | L26: 26.73 | M26: 26.39 | N26: 230.6 | O26: 2 | P26: 3.84 | Q26: 2.36 | R26: 2.35 | S26: 0.037 | T26: 1.58 | U26: 0 | V26: 18.6 | W26: 50.1
A27: 25 | B27: 43856 | C27: January | D27: Electronics | E27: 14 | F27: Swing | G27: 66 | H27: 3 | I27: =IFERROR(Table2[[#This Row],[Defects]]/Table2[[#This Row],[Units Produced]],"") -> 0.045454545 | J27: 5.84 | K27: =IFERROR(Table2[[#This Row],[Units Produced]]/Table2[[#This Row],[Production Time Hours]],"") -> 11.30137 | L27: 22.37 | M27: 16.8 | N27: 412.53 | O27: 1 | Q27: 2.63 | R27: 2.02 | S27: 0.036 | U27: 2 | V27: 21.9 | W27: 54.6
A28: 26 | B28: 43857 | C28: January | D28: Furniture | E28: 19 | F28: Swing | G28: 122 | H28: 9 | I28: =IFERROR(Table2[[#This Row],[Defects]]/Table2[[#This Row],[Units Produced]],"") -> 0.073770492 | J28: 15.74 | K28: =IFERROR(Table2[[#This Row],[Units Produced]]/Table2[[#This Row],[Production Time Hours]],"") -> 7.750953 | L28: 19.12 | M28: 27 | N28: 219.41 | O28: 1 | P28: 3.57 | Q28: 2.3 | R28: 0.73 | S28: 0.034 | T28: 1.69 | U28: 1 | V28: 18.7 | W28: 31.6
A29: 27 | B29: 43858 | C29: January | D29: Furniture | E29: 19 | F29: Day | G29: 83 | H29: 4 | I29: =IFERROR(Table2[[#This Row],[Defects]]/Table2[[#This Row],[Units Produced]],"") -> 0.048192771 | J29: 15.42 | K29: =IFERROR(Table2[[#This Row],[Units Produced]]/Table2[[#This Row],[Production Time Hours]],"") -> 5.38262 | L29: 41.52 | M29: 15.68 | N29: 491.62 | O29: 1 | P29: 0.47 | Q29: 1.24 | R29: 0.61 | S29: 0.043 | T29: 0.07 | U29: 1 | V29: 24.4 | W29: 51.7
A30: 28 | B30: 43859 | C30: January | D30: Appliances | E30: 12 | F30: Swing | G30: 95 | H30: 3 | I30: =IFERROR(Table2[[#This Row],[Defects]]/Table2[[#This Row],[Units Produced]],"") -> 0.031578947 | J30: 7.07 | K30: =IFERROR(Table2[[#This Row],[Units Produced]]/Table2[[#This Row],[Production Time Hours]],"") -> 13.437058 | L30: 13.7 | M30: 23.63 | N30: 254.49 | O30: 2 | P30: 3.86 | R30: 1.1 | S30: 0.049 | T30: 1.54 | U30: 0 | V30: 19.1 | W30: 42.3
A31: 29 | B31: 43860 | C31: January | D31: Automotive | E31: 3 | F31: Swing | G31: 132 | H31: 2 | I31: =IFERROR(Table2[[#This Row],[Defects]]/Table2[[#This Row],[Units Produced]],"") -> 0.015151515 | J31: 12.6 | K31: =IFERROR(Table2[[#This Row],[Units Produced]]/Table2[[#This Row],[Production Time Hours]],"") -> 10.47619 | L31: 29.43 | M31: 16.73 | N31: 105.2 | O31: 1 | P31: 3.89 | Q31: 1.77 | R31: 2.05 | S31: 0.015 | T31: 1.4 | U31: 1 | V31: 20.6 | W31: 53
A32: 30 | B32: 43861 | C32: January | D32: Electronics | E32: 15 | F32: Swing | G32: 143 | H32: 6 | I32: =IFERROR(Table2[[#This Row],[Defects]]/Table2[[#This Row],[Units Produced]],"") -> 0.041958042 | J32: 20.93 | K32: =IFERROR(Table2[[#This Row],[Units Produced]]/Table2[[#This Row],[Production Time Hours]],"") -> 6.8322981 | L32: 24.93 | M32: 24.03 | N32: 286.19 | O32: 3 | P32: 3.25 | Q32: 1.66 | R32: 2.22 | S32: 0.043 | U32: 1 | V32: 19.7 | W32: 49
A33: 31 | B33: 43862 | C33: February | D33: Electronics | E33: 14 | F33: Night | G33: 79 | H33: 9 | I33: =IFERROR(Table2[[#This Row],[Defects]]/Table2[[#This Row],[Units Produced]],"") -> 0.11392405 | J33: 19.29 | K33: =IFERROR(Table2[[#This Row],[Units Produced]]/Table2[[#This Row],[Production Time Hours]],"") -> 4.0953862 | L33: 35.31 | M33: 17.29 | N33: 482.31 | O33: 4 | P33: 0.96 | Q33: 1.27 | R33: 1.32 | S33: 0.039 | T33: 0.28 | U33: 1 | V33: 23 | W33: 39.6
A34: 32 | B34: 43863 | C34: February | D34: Appliances | E34: 11 | F34: Swing | G34: 189 | H34: 7 | I34: =IFERROR(Table2[[#This Row],[Defects]]/Table2[[#This Row],[Units Produced]],"") -> 0.037037037 | J34: 14.48 | K34: =IFERROR(Table2[[#This Row],[Units Produced]]/Table2[[#This Row],[Production Time Hours]],"") -> 13.052486 | L34: 60 | M34: 28.41 | N34: 353.47 | O34: 4 | P34: 2.5 | Q34: 1.9 | R34: 0.75 | S34: 0.028 | T34: 0.02 | U34: 0 | V34: 18.5 | W34: 58.4
A35: 33 | B35: 43864 | C35: February | D35: Appliances | E35: 12 | F35: Day | G35: 149 | H35: 0 | I35: =IFERROR(Table2[[#This Row],[Defects]]/Table2[[#This Row],[Units Produced]],"") -> 0 | J35: 16.35 | K35: =IFERROR(Table2[[#This Row],[Units Produced]]/Table2[[#This Row],[Production Time Hours]],"") -> 9.1131498 | L35: 23.87 | M35: 24.78 | N35: 140.89 | O35: 4 | P35: 0.16 | Q35: 0.13 | R35: 1.99 | S35: 0.024 | U35: 0 | V35: 19.4 | W35: 45.1
A36: 34 | B36: 43865 | C36: February | D36: Furniture | E36: 17 | F36: Swing | G36: 56 | H36: 4 | I36: =IFERROR(Table2[[#This Row],[Defects]]/Table2[[#This Row],[Units Produced]],"") -> 0.071428571 | J36: 1.81 | K36: =IFERROR(Table2[[#This Row],[Units Produced]]/Table2[[#This Row],[Production Time Hours]],"") -> 30.939227 | L36: 14.23 | M36: 21.59 | N36: 143.2 | O36: 4 | P36: 1.28 | Q36: 2.73 | R36: 2.18 | S36: 0.035 | T36: 0.62 | U36: 0 | V36: 22.5 | W36: 43.2
A37: 35 | B37: 43866 | C37: February | D37: Automotive | E37: 3 | F37: Night | G37: 167 | H37: 9 | I37: =IFERROR(Table2[[#This Row],[Defects]]/Table2[[#This Row],[Units Produced]],"") -> 0.053892216 | J37: 3.05 | K37: =IFERROR(Table2[[#This Row],[Units Produced]]/Table2[[#This Row],[Production Time Hours]],"") -> 54.754098 | L37: 15.45 | M37: 28.61 | N37: 279.58 | O37: 2 | P37: 3.36 | Q37: 0.91 | R37: 0.72 | S37: 0.039 | T37: 1.18 | U37: 0 | V37: 19.6 | W37: 47.3
A38: 36 | B38: 43867 | C38: February | D38: Furniture | E38: 19 | F38: Day | G38: 115 | H38: 6 | I38: =IFERROR(Table2[[#This Row],[Defects]]/Table2[[#This Row],[Units Produced]],"") -> 0.052173913 | J38: 9.62 | K38: =IFERROR(Table2[[#This Row],[Units Produced]]/Table2[[#This Row],[Production Time Hours]],"") -> 11.954262 | L38: 37.25 | M38: 17.59 | N38: 190.21 | O38: 3 | P38: 1.81 | Q38: 0.37 | R38: 1.35 | S38: 0.03 | T38: 0.66 | U38: 0 | V38: 22.9 | W38: 42.1
A39: 37 | B39: 43868 | C39: February | D39: Appliances | E39: 12 | F39: Day | G39: 198 | H39: 1 | I39: =IFERROR(Table2[[#This Row],[Defects]]/Table2[[#This Row],[Units Produced]],"") -> 0.0050505051 | J39: 9.82 | K39: =IFERROR(Table2[[#This Row],[Units Produced]]/Table2[[#This Row],[Production Time Hours]],"") -> 20.162933 | L39: 29.72 | M39: 28.17 | N39: 341.84 | O39: 3 | P39: 0.8 | Q39: 0.59 | R39: 1.78 | S39: 0.02 | U39: 1 | V39: 19.2 | W39: 31.3
A40: 38 | B40: 43869 | C40: February | D40: Appliances | E40: 9 | F40: Night | G40: 140 | H40: 5 | I40: =IFERROR(Table2[[#This Row],[Defects]]/Table2[[#This Row],[Units Produced]],"") -> 0.035714286 | J40: 7.85 | K40: =IFERROR(Table2[[#This Row],[Units Produced]]/Table2[[#This Row],[Production Time Hours]],"") -> 17.834395 | L40: 41.54 | M40: 16.7 | N40: 473.59 | O40: 1 | P40: 0.54 | Q40: 1.79 | R40: 2.01 | S40: 0.039 | T40: 1.91 | U40: 0 | V40: 22.6 | W40: 51.2
...

Sheet pivot
A1: Total Units Produced
A2: 365200
A4: Average of Defects (%)
A5: 0.038541797
A7: Production Time (Hours)
A8: 36739.75
A10: Average of Efficiency
A11: 17.371756
A13: Shift | B13: Total Units Produced
A14: Day | B14: 119058
A15: Night | B15: 121350
A16: Swing | B16: 124792
A17: Grand Total | B17: 365200
A19: Product | B19: Average of Defects (%)
A20: Appliances | B20: 0.037320464
A21: Automotive | B21: 0.036957367
A22: Electronics | B22: 0.040725907
A23: Furniture | B23: 0.039908033
A24: Textiles | B24: 0.038151675
A25: Grand Total | B25: 0.038541797
A27: Date | B27: Average of Defects (%)
A28: January | B28: 0.036426675
A29: February | B29: 0.040778954
A30: March | B30: 0.037566829
A31: April | B31: 0.040336315
A32: May | B32: 0.036511752
A33: June | B33: 0.037958123
A34: July | B34: 0.035870423
A35: August | B35: 0.043094629
A36: September | B36: 0.037499189
A37: October | B37: 0.040776201
A38: November | B38: 0.037651669
A39: December | B39: 0.038205979
A40: Grand Total | B40: 0.038541797
A42: Date | B42: Total Units Produced | C42: Average of Efficiency
A43: January | B43: 30824 | C43: 15.798251
A44: February | B44: 27875 | C44: 17.519713
A45: March | B45: 31326 | C45: 15.372413
A46: April | B46: 29441 | C46: 15.798468
A47: May | B47: 31558 | C47: 18.722253
...

Sheet pivot2
A1: Sum of Units Produced | B1: Average of Defects (%) | C1: Sum of Production Time Hours | D1: Average of Efficiency | E1: Sum of Defects
A2: 365200 | B2: 0.038541797 | C2: 36739.75 | D2: 17.371756 | E2: 12175
A4: ProType | B4: Sum of Units Produced | C4: Average of Defects (%) | D4: Sum of Defects
A5: Appliances | B5: 74679 | C5: 0.037320464 | D5: 2465
A6: Automotive | B6: 81016 | C6: 0.036957367 | D6: 2601
A7: Electronics | B7: 67476 | C7: 0.040725907 | D7: 2325
A8: Furniture | B8: 67651 | C8: 0.039908033 | D8: 2344
A9: Textiles | B9: 74378 | C9: 0.038151675 | D9: 2440
A10: Total | B10: 365200 | C10: 0.038541797 | D10: 12175
A12: ProType | B12: Sum of Units Produced | C12: Average of Defects (%) | D12: Average of Efficiency | E12: Sum of Production Time Hours
A13: Day | B13: 119058 | C13: 0.038673941 | D13: 17.392685 | E13: 12066.02
A14: Night | B14: 121350 | C14: 0.039100192 | D14: 17.37718 | E14: 12241.05
A15: Swing | B15: 124792 | C15: 0.037859542 | D15: 17.346042 | E15: 12432.68
A16: Total | B16: 365200 | C16: 0.038541797 | D16: 17.371756 | E16: 36739.75
A18: Date2 | B18: Years (Date)
A19: January | B19: 2020
B20: 2021
B21: 2022
B22: 2023
B23: 2024
B24: 2025
B25: 2026
B26: 2027
A27: February | B27: 2020
B28: 2021
B29: 2022
B30: 2023
B31: 2024
B32: 2025
B33: 2026
B34: 2027
A35: March | B35: 2020
B36: 2021
B37: 2022
B38: 2023
B39: 2024
B40: 2025
B41: 2026
B42: 2027
A43: April | B43: 2020
...

Sheet dashboard
A38: Ahmad Amir Hamzah - Excel Portfolio

Sheet report
F7: Periode:
F8: =CONCATENATE(pivot2!A19," ",pivot2!B19) -> January 2020
B14: Metric | C14: Value | D14: Unit / %
B15: Total Units Produced | C15: =GETPIVOTDATA("Sum of Units Produced",pivot2!$A$1) -> 365200 | D15: units
B16: Average Defect Rate | C16: =GETPIVOTDATA("Average of Defects (%)",pivot2!$A$1) -> 0.038541797 | D16: percentage
B17: Total Production Hours | C17: =GETPIVOTDATA("Sum of Production Time Hours",pivot2!$A$1) -> 36739.75 | D17: hours
B18: Average Efficiency | C18: =GETPIVOTDATA("Average of Efficiency",pivot2!$A$1) -> 17.371756 | D18: units/hour
B19: Total Defect | C19: =GETPIVOTDATA("Sum of Defects",pivot2!$A$1) -> 12175 | D19: units
B21: Product Type | C21: Total Units Produced | D21: Average of Defects (%) | E21: Total Defects
B22: Appliances | C22: =pivot2!B5 -> 74679 | D22: =pivot2!C5 -> 0.037320464 | E22: =pivot2!D5 -> 2465
B23: Automotive | C23: =pivot2!B6 -> 81016 | D23: =pivot2!C6 -> 0.036957367 | E23: =pivot2!D6 -> 2601
B24: Electronics | C24: =pivot2!B7 -> 67476 | D24: =pivot2!C7 -> 0.040725907 | E24: =pivot2!D7 -> 2325
B25: Furniture | C25: =pivot2!B8 -> 67651 | D25: =pivot2!C8 -> 0.039908033 | E25: =pivot2!D8 -> 2344
B26: Textiles | C26: =pivot2!B9 -> 74378 | D26: =pivot2!C9 -> 0.038151675 | E26: =pivot2!D9 -> 2440
B27: Total | C27: =pivot2!B10 -> 365200 | D27: =pivot2!C10 -> 0.038541797 | E27: =pivot2!D10 -> 12175
B30: Shift | C30: Total Units Produced | D30: Average of Defects (%) | E30: Efficiency (unit/hour) | F30: Production Time (hours)
B31: Day | C31: =C24 -> 67476 | D31: =D24 -> 0.040725907 | E31: =E24 -> 2325 | F31: =pivot2!E13 -> 12066.02
B32: Night | C32: =C25 -> 67651 | D32: =D25 -> 0.039908033 | E32: =E25 -> 2344 | F32: =pivot2!E14 -> 12241.05
B33: Swing | C33: =C26 -> 74378 | D33: =D26 -> 0.038151675 | E33: =E26 -> 2440 | F33: =pivot2!E15 -> 12432.68
B34: Total | C34: =C27 -> 365200 | D34: =D27 -> 0.038541797 | E34: =E27 -> 12175 | F34: =pivot2!E16 -> 36739.75
A62: Ahmad Amir Hamzah - Excel Portfolio
